Workbook

Sheet ĐỌC TRƯỚC
A1: PHIẾU TRẢI NGHIỆM · AI Tutor Trường Việt Anh
B3: Việc của bạn | C3: Dùng app như một HỌC SINH lớp 10 thật: vào học, làm bài, nộp bài, xem điểm. Rồi đổi sang tài khoản PHỤ HUYNH và GIÁO VIÊN của bạn để xem hai phía kia thấy gì.
B4: Không chia việc | C4: Cả ba người đi TRỌN luồng như nhau, từ đầu đến cuối. Ba góc nhìn khác nhau trên cùng một đường đi mới lộ ra chỗ hỏng.
B5: Mất bao lâu | C5: Khoảng 30–40 phút. Không cần làm một mạch.
B6: Địa chỉ | C6: https://tutor.vietanh.org — mở bằng Chrome hoặc Safari, cả máy tính lẫn điện thoại đều được.
B7: Điền vào đâu | C7: Sheet mang tên bạn (Người thử 1/2/3). Mỗi chặng có sẵn mô tả 'bạn sẽ thấy gì' — chỉ cần nói app có đúng như vậy không, và viết cảm nhận thật.
B8: Đáp án | C8: Sheet ĐÁP ÁN TOÁN 10 có sẵn lời giải 4 bài đầu, đúng thứ tự câu app hiện ra. Bạn KHÔNG phải giải toán — mục tiêu là thử app, không phải thi.
B9: Quan trọng nhất | C9: Cột 'Ghi chú' mới là thứ chúng tôi cần. Chỗ nào bạn khựng lại, đọc không hiểu, bấm nhầm, thấy xấu, thấy chậm — viết ra, càng cụ thể càng tốt.
B11: TÀI KHOẢN CỦA BẠN (mỗi người 3 tài khoản — dùng đúng bộ của mình)
B12: Người thử | C12: Học sinh | D12: Phụ huynh | E12: Giáo viên | F12: Mật khẩu
B13: Người thử 1 | C13: hs2@vietanh.edu.vn | D13: ph2@vietanh.edu.vn | E13: gv2@vietanh.edu.vn
B14: Người thử 2 | C14: hs3@vietanh.edu.vn | D14: ph3@vietanh.edu.vn | E14: gv3@vietanh.edu.vn
B15: Người thử 3 | C15: hs4@vietanh.edu.vn | D15: ph4@vietanh.edu.vn | E15: gv4@vietanh.edu.vn
B16: Ô mật khẩu để trống — người quản trị điền tay rồi mới gửi file đi.
B18: MẸO: gặp lỗi thì chụp màn hình rồi gửi kèm, đặt tên ảnh theo số chặng (ví dụ 'chặng 6 - lỗi.png'). Nếu app đứng hình hoặc báo lỗi lạ, thử tải lại trang một lần rồi ghi lại xem có hết không.

Sheet Người thử 1
A1: Người thử 1 — tài khoản học sinh: hs2@vietanh.edu.vn
A2: Đi từ trên xuống. Cột D là điều BÌNH THƯỜNG phải thấy — app khác đi là có chuyện, ghi vào cột G.
B4: Chặng | C4: Bạn làm gì | D4: Bạn sẽ thấy gì | E4: Đúng như mô tả? | F4: Dễ dùng? (1–5) | G4: Ghi chú của bạn
A5: 1 | B5: A. Vào app | C5: Mở tutor.vietanh.org, đăng nhập bằng tài khoản HỌC SINH của bạn. | D5: Màn hình chào có con sư tử, rồi tới trang chọn môn.
A6: 2 | C6: Chọn môn Toán 10. | D6: Hiện 'lộ trình bàn chân' — một dãy bàn chân đi từ dưới lên, chia theo chương. Bàn chân đang sáng là bài bạn được học; các bài sau bị khoá.
A7: 3 | B7: B. Học bài đầu | C7: Bấm vào bàn chân đang sáng. | D7: Vào bài 'Khái niệm mệnh đề logic'. Có thanh tiến độ ở trên, đề bài ở giữa, nút KIỂM TRA ở dưới. Bài này có 8 câu, thứ tự cố định (dễ → khó).
A8: 4 | C8: Làm câu 1 đến câu 4 (đáp án ở sheet ĐÁP ÁN TOÁN 10, bài 1). | D8: Câu 1 và 4: bấm chọn 1 trong 4 ô. Câu 2: chọn Đúng/Sai cho từng ý a,b,c,d. Câu 3: gõ chữ vào ô. Trả lời đúng thì sư tử reo và cộng XP.
A9: 5 | C9: CỐ TÌNH chọn sai một câu để xem app phản ứng thế nào. | D9: Sư tử hiện lên kèm câu nhắc 'thử lại' — KHÔNG cho đáp án, chỉ gợi ý nghĩ lại. Bấm THỬ LẠI là làm lại được ngay.
A10: 6 | B10: C. Câu nhiều bước | C10: Làm câu 5 — đề chia thành Bước 1, Bước 2, Bước 3. | D10: Mỗi bước là một thẻ riêng. Bước có (Có/Không) hiện hai nút to; trả lời xong bước này mới mở bước sau. Bước cuối có ô gõ kết luận.
A11: 7 | B11: D. Nộp bài tự luận | C11: Làm câu 6 — câu này là dạng NỘP BÀI (đáp án dài). | D11: Có ô lớn 'Viết bài làm của em ở đây', bên dưới là dòng 'Đính kèm ảnh bài làm' (tuỳ chọn). Gõ vài câu rồi bấm NỘP BÀI.
A12: 8 | C12: Xem app chấm bài gõ của bạn. | D12: Hiện 'Đang suy nghĩ…' vài giây, rồi trợ lý nói bài đủ ý hay còn thiếu ý gì. Thiếu ý thì còn nút NỘP LẠI để bổ sung. Thầy cô vẫn xem lại sau.
A13: 9 | C13: Thử nộp bằng ẢNH: chụp/chọn một ảnh bất kỳ rồi nộp (câu 7 hoặc 8). | D13: Tên tệp hiện ra cạnh cái kẹp giấy, có nút X để gỡ. Nộp xong app nói đã nhận, chờ thầy cô chấm.
A14: 10 | B14: E. Sau khi học | C14: Làm nốt các câu còn lại rồi thoát ra lộ trình. | D14: Bàn chân bài vừa học hiện số câu đã làm (ví dụ 6/8) và nhãn 'chờ chấm' nếu còn bài đang đợi thầy cô. Học đủ và chắc thì bàn chân chuyển xanh.
A15: 11 | C15: Bấm lần lượt 4 mục dưới cùng: Ôn tập, Hạng, Mục tiêu, Tôi. | D15: Ôn tập: các câu từng sai. Hạng: bảng xếp hạng + XP hôm nay. Mục tiêu: việc cần làm. Tôi: hồ sơ, đổi mật khẩu.
A16: 12 | B16: F. Phía phụ huynh | C16: Đăng xuất, đăng nhập bằng tài khoản PHỤ HUYNH của bạn (trang 'Theo dõi con'). | D16: 'Báo cáo tuần' của đúng đứa con vừa học: tên con, số điểm đã thành thạo / đang luyện thêm, tiến độ mục tiêu. Báo cáo nói về NỖ LỰC và TIẾN BỘ — không có nội dung con trò chuyện với trợ lý.
A17: 13 | B17: G. Phía giáo viên | C17: Đăng xuất, đăng nhập bằng tài khoản GIÁO VIÊN của bạn. Trang có 5 tab: Tổng quan · Học sinh · Chủ đề · Chấm bài · Duyệt & nội dung. Vào tab CHẤM BÀI. | D17: Tab Chấm bài có con số bài đang chờ. Bên trong là đúng bài bạn vừa nộp: tên học sinh, đề bài, bài làm em gõ, đáp án mẫu để đối chiếu, và dòng 'AI sơ khảo' đã chấm trước.
A18: 14 | C18: Chấm một bài CHƯA ĐẠT (kèm lời nhắn), một bài ĐẠT. | D18: Chấm xong bài rời khỏi hàng đợi. Bài nộp lại nhiều lần của cùng một câu chỉ hiện MỘT dòng — không phải chấm trùng.
A19: 15 | B19: H. Vòng khép kín | C19: Quay lại tài khoản HỌC SINH, mở lộ trình. | D19: Bài bị chấm 'chưa đạt' hiện BÀN CHÂN ĐỎ kèm lời mời làm lại. Bài chấm 'đạt' thì được tính, XP tăng.
A20: 16 | B20: I. Trên điện thoại | C20: Mở lại tutor.vietanh.org bằng điện thoại, làm thử 2–3 câu. | D20: Chữ đủ to, nút bấm không bị dính nhau, bàn phím không che mất nút, không phải kéo ngang.
B22: NÓI THẬT GIÙM CHÚNG TÔI
B23: Điều bạn THÍCH nhất khi dùng app:
B24: Điều làm bạn KHÓ CHỊU nhất (dù nhỏ):
B25: Chỗ nào bạn nghĩ học sinh lớp 10 sẽ khựng lại / không hiểu phải làm gì?
B26: Bạn có sẵn sàng cho lớp mình dùng app này không? Vì sao?

Sheet Người thử 2
A1: Người thử 2 — tài khoản học sinh: hs3@vietanh.edu.vn
A2: Đi từ trên xuống. Cột D là điều BÌNH THƯỜNG phải thấy — app khác đi là có chuyện, ghi vào cột G.
B4: Chặng | C4: Bạn làm gì | D4: Bạn sẽ thấy gì | E4: Đúng như mô tả? | F4: Dễ dùng? (1–5) | G4: Ghi chú của bạn
A5: 1 | B5: A. Vào app | C5: Mở tutor.vietanh.org, đăng nhập bằng tài khoản HỌC SINH của bạn. | D5: Màn hình chào có con sư tử, rồi tới trang chọn môn.
A6: 2 | C6: Chọn môn Toán 10. | D6: Hiện 'lộ trình bàn chân' — một dãy bàn chân đi từ dưới lên, chia theo chương. Bàn chân đang sáng là bài bạn được học; các bài sau bị khoá.
A7: 3 | B7: B. Học bài đầu | C7: Bấm vào bàn chân đang sáng. | D7: Vào bài 'Khái niệm mệnh đề logic'. Có thanh tiến độ ở trên, đề bài ở giữa, nút KIỂM TRA ở dưới. Bài này có 8 câu, thứ tự cố định (dễ → khó).
A8: 4 | C8: Làm câu 1 đến câu 4 (đáp án ở sheet ĐÁP ÁN TOÁN 10, bài 1). | D8: Câu 1 và 4: bấm chọn 1 trong 4 ô. Câu 2: chọn Đúng/Sai cho từng ý a,b,c,d. Câu 3: gõ chữ vào ô. Trả lời đúng thì sư tử reo và cộng XP.
A9: 5 | C9: CỐ TÌNH chọn sai một câu để xem app phản ứng thế nào. | D9: Sư tử hiện lên kèm câu nhắc 'thử lại' — KHÔNG cho đáp án, chỉ gợi ý nghĩ lại. Bấm THỬ LẠI là làm lại được ngay.
A10: 6 | B10: C. Câu nhiều bước | C10: Làm câu 5 — đề chia thành Bước 1, Bước 2, Bước 3. | D10: Mỗi bước là một thẻ riêng. Bước có (Có/Không) hiện hai nút to; trả lời xong bước này mới mở bước sau. Bước cuối có ô gõ kết luận.
A11: 7 | B11: D. Nộp bài tự luận | C11: Làm câu 6 — câu này là dạng NỘP BÀI (đáp án dài). | D11: Có ô lớn 'Viết bài làm của em ở đây', bên dưới là dòng 'Đính kèm ảnh bài làm' (tuỳ chọn). Gõ vài câu rồi bấm NỘP BÀI.
A12: 8 | C12: Xem app chấm bài gõ của bạn. | D12: Hiện 'Đang suy nghĩ…' vài giây, rồi trợ lý nói bài đủ ý hay còn thiếu ý gì. Thiếu ý thì còn nút NỘP LẠI để bổ sung. Thầy cô vẫn xem lại sau.
A13: 9 | C13: Thử nộp bằng ẢNH: chụp/chọn một ảnh bất kỳ rồi nộp (câu 7 hoặc 8). | D13: Tên tệp hiện ra cạnh cái kẹp giấy, có nút X để gỡ. Nộp xong app nói đã nhận, chờ thầy cô chấm.
A14: 10 | B14: E. Sau khi học | C14: Làm nốt các câu còn lại rồi thoát ra lộ trình. | D14: Bàn chân bài vừa học hiện số câu đã làm (ví dụ 6/8) và nhãn 'chờ chấm' nếu còn bài đang đợi thầy cô. Học đủ và chắc thì bàn chân chuyển xanh.
A15: 11 | C15: Bấm lần lượt 4 mục dưới cùng: Ôn tập, Hạng, Mục tiêu, Tôi. | D15: Ôn tập: các câu từng sai. Hạng: bảng xếp hạng + XP hôm nay. Mục tiêu: việc cần làm. Tôi: hồ sơ, đổi mật khẩu.
A16: 12 | B16: F. Phía phụ huynh | C16: Đăng xuất, đăng nhập bằng tài khoản PHỤ HUYNH của bạn (trang 'Theo dõi con'). | D16: 'Báo cáo tuần' của đúng đứa con vừa học: tên con, số điểm đã thành thạo / đang luyện thêm, tiến độ mục tiêu. Báo cáo nói về NỖ LỰC và TIẾN BỘ — không có nội dung con trò chuyện với trợ lý.
A17: 13 | B17: G. Phía giáo viên | C17: Đăng xuất, đăng nhập bằng tài khoản GIÁO VIÊN của bạn. Trang có 5 tab: Tổng quan · Học sinh · Chủ đề · Chấm bài · Duyệt & nội dung. Vào tab CHẤM BÀI. | D17: Tab Chấm bài có con số bài đang chờ. Bên trong là đúng bài bạn vừa nộp: tên học sinh, đề bài, bài làm em gõ, đáp án mẫu để đối chiếu, và dòng 'AI sơ khảo' đã chấm trước.
A18: 14 | C18: Chấm một bài CHƯA ĐẠT (kèm lời nhắn), một bài ĐẠT. | D18: Chấm xong bài rời khỏi hàng đợi. Bài nộp lại nhiều lần của cùng một câu chỉ hiện MỘT dòng — không phải chấm trùng.
A19: 15 | B19: H. Vòng khép kín | C19: Quay lại tài khoản HỌC SINH, mở lộ trình. | D19: Bài bị chấm 'chưa đạt' hiện BÀN CHÂN ĐỎ kèm lời mời làm lại. Bài chấm 'đạt' thì được tính, XP tăng.
A20: 16 | B20: I. Trên điện thoại | C20: Mở lại tutor.vietanh.org bằng điện thoại, làm thử 2–3 câu. | D20: Chữ đủ to, nút bấm không bị dính nhau, bàn phím không che mất nút, không phải kéo ngang.
B22: NÓI THẬT GIÙM CHÚNG TÔI
B23: Điều bạn THÍCH nhất khi dùng app:
B24: Điều làm bạn KHÓ CHỊU nhất (dù nhỏ):
B25: Chỗ nào bạn nghĩ học sinh lớp 10 sẽ khựng lại / không hiểu phải làm gì?
B26: Bạn có sẵn sàng cho lớp mình dùng app này không? Vì sao?

Sheet Người thử 3
A1: Người thử 3 — tài khoản học sinh: hs4@vietanh.edu.vn
A2: Đi từ trên xuống. Cột D là điều BÌNH THƯỜNG phải thấy — app khác đi là có chuyện, ghi vào cột G.
B4: Chặng | C4: Bạn làm gì | D4: Bạn sẽ thấy gì | E4: Đúng như mô tả? | F4: Dễ dùng? (1–5) | G4: Ghi chú của bạn
A5: 1 | B5: A. Vào app | C5: Mở tutor.vietanh.org, đăng nhập bằng tài khoản HỌC SINH của bạn. | D5: Màn hình chào có con sư tử, rồi tới trang chọn môn.
A6: 2 | C6: Chọn môn Toán 10. | D6: Hiện 'lộ trình bàn chân' — một dãy bàn chân đi từ dưới lên, chia theo chương. Bàn chân đang sáng là bài bạn được học; các bài sau bị khoá.
A7: 3 | B7: B. Học bài đầu | C7: Bấm vào bàn chân đang sáng. | D7: Vào bài 'Khái niệm mệnh đề logic'. Có thanh tiến độ ở trên, đề bài ở giữa, nút KIỂM TRA ở dưới. Bài này có 8 câu, thứ tự cố định (dễ → khó).
A8: 4 | C8: Làm câu 1 đến câu 4 (đáp án ở sheet ĐÁP ÁN TOÁN 10, bài 1). | D8: Câu 1 và 4: bấm chọn 1 trong 4 ô. Câu 2: chọn Đúng/Sai cho từng ý a,b,c,d. Câu 3: gõ chữ vào ô. Trả lời đúng thì sư tử reo và cộng XP.
A9: 5 | C9: CỐ TÌNH chọn sai một câu để xem app phản ứng thế nào. | D9: Sư tử hiện lên kèm câu nhắc 'thử lại' — KHÔNG cho đáp án, chỉ gợi ý nghĩ lại. Bấm THỬ LẠI là làm lại được ngay.
A10: 6 | B10: C. Câu nhiều bước | C10: Làm câu 5 — đề chia thành Bước 1, Bước 2, Bước 3. | D10: Mỗi bước là một thẻ riêng. Bước có (Có/Không) hiện hai nút to; trả lời xong bước này mới mở bước sau. Bước cuối có ô gõ kết luận.
A11: 7 | B11: D. Nộp bài tự luận | C11: Làm câu 6 — câu này là dạng NỘP BÀI (đáp án dài). | D11: Có ô lớn 'Viết bài làm của em ở đây', bên dưới là dòng 'Đính kèm ảnh bài làm' (tuỳ chọn). Gõ vài câu rồi bấm NỘP BÀI.
A12: 8 | C12: Xem app chấm bài gõ của bạn. | D12: Hiện 'Đang suy nghĩ…' vài giây, rồi trợ lý nói bài đủ ý hay còn thiếu ý gì. Thiếu ý thì còn nút NỘP LẠI để bổ sung. Thầy cô vẫn xem lại sau.
A13: 9 | C13: Thử nộp bằng ẢNH: chụp/chọn một ảnh bất kỳ rồi nộp (câu 7 hoặc 8). | D13: Tên tệp hiện ra cạnh cái kẹp giấy, có nút X để gỡ. Nộp xong app nói đã nhận, chờ thầy cô chấm.
A14: 10 | B14: E. Sau khi học | C14: Làm nốt các câu còn lại rồi thoát ra lộ trình. | D14: Bàn chân bài vừa học hiện số câu đã làm (ví dụ 6/8) và nhãn 'chờ chấm' nếu còn bài đang đợi thầy cô. Học đủ và chắc thì bàn chân chuyển xanh.
A15: 11 | C15: Bấm lần lượt 4 mục dưới cùng: Ôn tập, Hạng, Mục tiêu, Tôi. | D15: Ôn tập: các câu từng sai. Hạng: bảng xếp hạng + XP hôm nay. Mục tiêu: việc cần làm. Tôi: hồ sơ, đổi mật khẩu.
A16: 12 | B16: F. Phía phụ huynh | C16: Đăng xuất, đăng nhập bằng tài khoản PHỤ HUYNH của bạn (trang 'Theo dõi con'). | D16: 'Báo cáo tuần' của đúng đứa con vừa học: tên con, số điểm đã thành thạo / đang luyện thêm, tiến độ mục tiêu. Báo cáo nói về NỖ LỰC và TIẾN BỘ — không có nội dung con trò chuyện với trợ lý.
A17: 13 | B17: G. Phía giáo viên | C17: Đăng xuất, đăng nhập bằng tài khoản GIÁO VIÊN của bạn. Trang có 5 tab: Tổng quan · Học sinh · Chủ đề · Chấm bài · Duyệt & nội dung. Vào tab CHẤM BÀI. | D17: Tab Chấm bài có con số bài đang chờ. Bên trong là đúng bài bạn vừa nộp: tên học sinh, đề bài, bài làm em gõ, đáp án mẫu để đối chiếu, và dòng 'AI sơ khảo' đã chấm trước.
A18: 14 | C18: Chấm một bài CHƯA ĐẠT (kèm lời nhắn), một bài ĐẠT. | D18: Chấm xong bài rời khỏi hàng đợi. Bài nộp lại nhiều lần của cùng một câu chỉ hiện MỘT dòng — không phải chấm trùng.
A19: 15 | B19: H. Vòng khép kín | C19: Quay lại tài khoản HỌC SINH, mở lộ trình. | D19: Bài bị chấm 'chưa đạt' hiện BÀN CHÂN ĐỎ kèm lời mời làm lại. Bài chấm 'đạt' thì được tính, XP tăng.
A20: 16 | B20: I. Trên điện thoại | C20: Mở lại tutor.vietanh.org bằng điện thoại, làm thử 2–3 câu. | D20: Chữ đủ to, nút bấm không bị dính nhau, bàn phím không che mất nút, không phải kéo ngang.
B22: NÓI THẬT GIÙM CHÚNG TÔI
B23: Điều bạn THÍCH nhất khi dùng app:
B24: Điều làm bạn KHÓ CHỊU nhất (dù nhỏ):
B25: Chỗ nào bạn nghĩ học sinh lớp 10 sẽ khựng lại / không hiểu phải làm gì?
B26: Bạn có sẵn sàng cho lớp mình dùng app này không? Vì sao?

Sheet ĐÁP ÁN TOÁN 10
A1: ĐÁP ÁN 4 BÀI ĐẦU — Toán 10 (đúng thứ tự câu app hiện ra)
A2: Thứ tự câu và thứ tự 4 phương án đều CỐ ĐỊNH — mở lại bài vẫn y hệt, nên bảng này luôn khớp. Câu ghi 'NỘP BÀI' thì gõ ý chính là đủ, không cần chép nguyên văn.
A4: BÀI 1 · Khái niệm mệnh đề logic (Chương I. Mệnh đề và Tập hợp)
A5: # | B5: Dạng | C5: Đề bài | D5: Đáp án | E5: Ghi chú
A6: 1 | B6: Trắc nghiệm | C6: Câu nào sau đây là một mệnh đề? A. Số 7 là số nguyên tố. B. Bạn có khoẻ không? C. Hãy đóng cửa lại! D. x + 3 = 5. | D6: A — Số 7 là số nguyên tố. | E6: Bấm chọn 1 trong 4 ô
A7: 2 | B7: Đúng/Sai từng ý | C7: Xét mỗi ý sau là Đúng hay Sai: a) 'Hà Nội là thủ đô của Việt Nam' là một mệnh đề. b) 'Ôi trời đẹp quá!' là một mệnh đề. c) Một mệnh đề có thể vừa đúng vừa sai. d) Mệnh đề sai vẫn được coi là mệnh đề. | D7: a) Đúng; b) Sai; c) Sai; d) Đúng | E7: Chọn Đúng/Sai cho từng ý a→d
A8: 3 | B8: Trắc nghiệm | C8: Điền vào chỗ trống: 'Mệnh đề là một câu ___ , hoặc đúng hoặc sai, và không thể vừa đúng vừa sai.' | D8: khẳng định | E8: Bấm chọn 1 trong 4 ô
A9: 4 | B9: Trắc nghiệm | C9: Trong các câu sau, có bao nhiêu câu KHÔNG phải mệnh đề? (1) 2 + 2 = 5 (2) Mấy giờ rồi? (3) Số π là số vô tỉ. (4) n là số chẵn. (5) Cấm hút thuốc! Giải thích ngắn lựa chọn của em. | D9: 3 câu — gồm (2), (4), (5) | E9: Bấm chọn 1 trong 4 ô
A10: 5 | B10: Nhiều bước | C10: Xét câu: 'Nếu trời mưa thì đường ướt.' Bước 1: Câu này có phải câu khẳng định không? (Có/Không) Bước 2: Câu này có xác định được đúng hay sai không? (Có/Không) Bước 3: Kết luận câu này có phải mệnh đề không? | D10: Bước 1: Có; Bước 2: Có; Bước 3: Có — là mệnh đề (mệnh đề kéo theo) | E10: Trả lời lần lượt từng bước
A11: 6 | B11: NỘP BÀI | C11: Một bạn viết: 'Câu x² ≥ 0 là mệnh đề đúng, vì bình phương luôn không âm. Còn câu x + 1 = 4 cũng là mệnh đề, nó sai khi x = 2.' Hãy tìm và sửa lỗi trong lập luận trên. | D11: Lỗi: coi 'x + 1 = 4' là mệnh đề. Đây là MỆNH ĐỀ CHỨA BIẾN — chưa gán x thì chưa có giá trị chân lí cố định. (Câu x² ≥ 0 với mọi x thực thì đúng là mệnh đề đúng nếu ngầm hiểu ∀x, nhưng cần ghi rõ lượng từ.) | E11: Gõ ý chính là đủ — AI chấm ngay
A12: 7 | B12: NỘP BÀI | C12: Bạn Nam nói: 'Câu nào cũng có thể xác định đúng hay sai, chỉ là ta chưa đủ thông tin thôi. Vậy câu nào cũng là mệnh đề.' Em có đồng ý không? Hãy phản bác bằng ít nhất 2 phản ví dụ thuộc 2 loại câu khác nhau. | D12: Không đồng ý. Phản ví dụ: (1) 'Bạn tên gì?' — câu hỏi, không mang nội dung khẳng định nên không thể gán đúng/sai. (2) 'Hãy im lặng!' — câu cầu khiến. (3) 'x > 5' — chứa biến, giá trị chân lí thay đổi theo x. | E12: Gõ ý chính là đủ — AI chấm ngay
A13: 8 | B13: NỘP BÀI | C13: AI đóng vai bé Na lớp 6, bé hỏi: 'Sao câu 2+2=5 sai rành rành mà thầy vẫn bảo nó là mệnh đề? Sai thì đâu có được tính chứ?' Em hãy giải thích cho bé Na hiểu, có kèm ví dụ đời thường. | D13: Giải thích: mệnh đề không cần ĐÚNG, chỉ cần XÁC ĐỊNH được là đúng hay sai. Ví dụ đời thường: 'Hôm nay là thứ Ba' — nếu hôm nay thứ Hai thì câu này sai, nhưng nó vẫn là một lời khẳng định rõ ràng, ta gọi là mệnh đề (mệnh đề sai). | E13: Gõ ý chính là đủ — AI chấm ngay
A15: BÀI 2 · Xác định tính đúng/sai của mệnh đề (Chương I. Mệnh đề và Tập hợp)
A16: # | B16: Dạng | C16: Đề bài | D16: Đáp án | E16: Ghi chú
A17: 1 | B17: Trắc nghiệm | C17: Mệnh đề nào sau đây ĐÚNG? A. 5 là số chẵn. B. Mọi số nguyên tố đều lẻ. C. 9 chia hết cho 3. D. √4 = ±2. | D17: C — 9 chia hết cho 3. | E17: Bấm chọn 1 trong 4 ô
A18: 2 | B18: Đúng/Sai từng ý | C18: Xét tính đúng/sai của mỗi mệnh đề: a) 7 là số nguyên tố. b) 0 là số tự nhiên. c) −3 > −1. d) Số 1 là số nguyên tố. | D18: a) Đúng; b) Đúng; c) Sai; d) Sai | E18: Chọn Đúng/Sai cho từng ý a→d
A19: 3 | B19: Gõ đáp án | C19: Mệnh đề 'Số 12 chia hết cho 5' có giá trị chân lí là ___ (đúng/sai). | D19: sai | E19: Gõ vào ô rồi bấm KIỂM TRA
A20: 4 | B20: Trắc nghiệm | C20: Cho mệnh đề P: 'Mọi số thực x đều thoả x² > 0'. Khẳng định nào đúng? Giải thích ngắn. | D20: P sai, vì x = 0 cho 0² = 0, không lớn hơn 0. | E20: Bấm chọn 1 trong 4 ô
A21: 5 | B21: Nhiều bước | C21: Xét mệnh đề P: 'Tồn tại số tự nhiên n sao cho n² + n + 41 là hợp số.' Bước 1: Để chứng minh mệnh đề dạng 'tồn tại' là ĐÚNG, ta cần làm gì? Bước 2: Thử n = 41, tính n² + n + 41. Bước 3: Kết luận P đúng hay sai. | D21: B1: chỉ cần chỉ ra MỘT giá trị thoả mãn. B2: 41² + 41 + 41 = 1681 + 82 = 1763 = 41 × 43 → hợp số. B3: P ĐÚNG. | E21: Trả lời lần lượt từng bước
A22: 6 | B22: NỘP BÀI | C22: Lời giải của một bạn: 'Mệnh đề: Mọi số nguyên n đều thoả n² ≥ n. Chứng minh: thử n = 1 được 1 ≥ 1 đúng; n = 2 được 4 ≥ 2 đúng; n = 3 được 9 ≥ 3 đúng. Vậy mệnh đề ĐÚNG.' Tìm và sửa lỗi. | D22: Lỗi 1 (phương pháp): thử vài trường hợp KHÔNG chứng minh được mệnh đề với ∀. Lỗi 2 (kết luận): mệnh đề này thực ra ĐÚNG trên Z, nhưng phải chứng minh tổng quát: n² − n = n(n−1) là tích hai số nguyên liên tiếp nên ≥ 0 với mọi n nguyên. | E22: Gõ ý chính là đủ — AI chấm ngay
A23: 7 | B23: NỘP BÀI | C23: Vì sao muốn BÁC BỎ mệnh đề 'Mọi ...' ta chỉ cần MỘT phản ví dụ, còn muốn KHẲNG ĐỊNH nó thì thử một trăm ví dụ vẫn chưa đủ? Giải thích và cho một ví dụ toán học minh hoạ. | D23: Vì 'Mọi x, P(x)' yêu cầu P đúng với TẤT CẢ x; chỉ cần một x làm P sai là toàn bộ khẳng định sụp đổ. Ngược lại, thử 100 ví dụ chỉ chứng tỏ P đúng trên 100 phần tử đó, không nói gì về các phần tử còn lại. Ví dụ: 'n² − n + 41 nguyên tố với mọi n ∈ N' đúng với n = 0..40 nhưng sai tại n = 41. | E23: Gõ ý chính là đủ — AI chấm ngay
A24: 8 | B24: NỘP BÀI | C24: Bé Na lớp 6 nói: 'Em thử 1, 2, 3, 4, 5 đều thấy đúng rồi mà, sao thầy vẫn bảo em chưa chứng minh được?' Hãy giải thích cho bé bằng ngôn ngữ dễ hiểu, kèm một ví dụ 'bẫy' để bé thấy nguy hiểm của việc thử vài trường hợp. | D24: Giải thích: thử vài số giống như nếm vài quả trong một sọt rất lớn — ngon vài quả không có nghĩa cả sọt đều ngon. Ví dụ bẫy: n² − n + 41 cho ra số nguyên tố ở n = 1, 2, 3, ..., 40, nhưng đến n = 41 thì hỏng (ra 41², là hợp số). | E24: Gõ ý chính là đủ — AI chấm ngay
A26: BÀI 3 · Mệnh đề chứa biến (Chương I. Mệnh đề và Tập hợp)
A27: # | B27: Dạng | C27: Đề bài | D27: Đáp án | E27: Ghi chú
A28: 1 | B28: Trắc nghiệm | C28: Câu nào sau đây là MỆNH ĐỀ CHỨA BIẾN? A. 3 + 4 = 7 B. n là số chẵn (n ∈ N) C. Hà Nội là thủ đô Việt Nam. D. Bạn học lớp mấy? | D28: B — n là số chẵn (n ∈ N) | E28: Bấm chọn 1 trong 4 ô
A29: 2 | B29: Đúng/Sai từng ý | C29: Cho P(x): 'x² = 4' với x ∈ R. Xét từng ý: a) P(x) là một mệnh đề. b) P(2) là mệnh đề đúng. c) P(−2) là mệnh đề sai. d) P(x) trở thành mệnh đề khi gán x một giá trị cụ thể. | D29: a) Sai; b) Đúng; c) Sai; d) Đúng | E29: Chọn Đúng/Sai cho từng ý a→d
A30: 3 | B30: Trắc nghiệm | C30: Điền: 'Mệnh đề chứa biến trở thành một ___ khi ta thay biến bằng một giá trị cụ thể thuộc tập xác định.' | D30: mệnh đề | E30: Bấm chọn 1 trong 4 ô
A31: 4 | B31: Trắc nghiệm | C31: Cho P(n): 'n chia hết cho 3', n ∈ {1;2;3;...;10}. Có bao nhiêu giá trị n làm P(n) ĐÚNG? Giải thích ngắn. | D31: 3 giá trị (n = 3; 6; 9) | E31: Bấm chọn 1 trong 4 ô
A32: 5 | B32: NỘP BÀI | C32: Cho P(n): 'n² < 2n' với n ∈ N. Bước 1: Tính P(0), P(1), P(2), P(3) và ghi rõ đúng/sai. Bước 2: Liệt kê các n làm P(n) đúng. Bước 3: P(n) có phải mệnh đề không? Vì sao? | D32: B1: P(0): 0 < 0 SAI; P(1): 1 < 2 ĐÚNG; P(2): 4 < 4 SAI; P(3): 9 < 6 SAI. B2: chỉ n = 1. B3: P(n) KHÔNG phải mệnh đề — là mệnh đề chứa biến, vì chân lí thay đổi theo n. | E32: Gõ ý chính là đủ — AI chấm ngay
A33: 6 | B33: NỘP BÀI | C33: Một bạn viết: 'Cho P(x): x² ≥ x với x ∈ R. Vì P(2) đúng, P(3) đúng, P(10) đúng nên P(x) là MỆNH ĐỀ ĐÚNG.' Tìm và sửa lỗi. | D33: Có 2 lỗi. Lỗi 1: gọi P(x) là 'mệnh đề' — nó là mệnh đề CHỨA BIẾN. Lỗi 2: nếu ngầm hiểu là ∀x ∈ R thì mệnh đề SAI (phản ví dụ x = 0.5: 0.25 < 0.5). Sửa: 'P(x) là mệnh đề chứa biến; mệnh đề ∀x ∈ R, P(x) là SAI vì x = 0.5 là phản ví dụ.' | E33: Gõ ý chính là đủ — AI chấm ngay
A34: 7 | B34: Gõ đáp án | C34: Giải thích sự khác nhau giữa ba đối tượng sau, nêu rõ cái nào có giá trị chân lí: (1) x + 2 = 5 (2) 'Với mọi x ∈ R, x + 2 = 5' (3) '3 + 2 = 5' | D34: (1) Mệnh đề chứa biến — chưa có chân lí, chỉ có tập nghiệm {3}. (2) Là MỆNH ĐỀ (đã có lượng từ), và nó SAI vì x = 0 không thoả. (3) Là mệnh đề, và ĐÚNG. | E34: Gõ vào ô rồi bấm KIỂM TRA
A35: 8 | B35: NỘP BÀI | C35: Bé Na hỏi: 'Câu x + 1 = 3 rõ ràng ai cũng biết x = 2, sao lại bảo nó chưa đúng chưa sai?' Hãy giải thích cho bé, dùng một hình ảnh so sánh đời thường. | D35: Giải thích: câu 'x + 1 = 3' giống như một cái ô trống trong tờ khai — chưa điền thì chưa biết đúng hay sai. Điền x = 2 thì thành 'đúng'; điền x = 5 thì thành 'sai'. Vì chân lí đổi theo cái ta điền vào nên bản thân câu ấy chưa phải mệnh đề. Việc 'giải ra x = 2' là tìm giá trị làm nó ĐÚNG, chứ không phải câu ấy vốn đúng. | E35: Gõ ý chính là đủ — AI chấm ngay
A37: BÀI 4 · Mệnh đề phủ định và kí hiệu (Chương I. Mệnh đề và Tập hợp)
A38: # | B38: Dạng | C38: Đề bài | D38: Đáp án | E38: Ghi chú
A39: 1 | B39: Trắc nghiệm | C39: Cho mệnh đề P: '5 là số chẵn'. Mệnh đề phủ định P̄ là: A. 5 là số lẻ. B. 5 không phải là số chẵn. C. 6 là số chẵn. D. 5 là số nguyên tố. | D39: B — 5 không phải là số chẵn. | E39: Bấm chọn 1 trong 4 ô
A40: 2 | B40: Đúng/Sai từng ý | C40: Cho P: '12 chia hết cho 5'. Xét từng ý: a) P sai. b) Kí hiệu phủ định của P là P̄. c) P̄: '12 không chia hết cho 5'. d) P̄ sai. | D40: a) Đúng; b) Đúng; c) Đúng; d) Sai | E40: Chọn Đúng/Sai cho từng ý a→d
A41: 3 | B41: Gõ đáp án | C41: Điền: 'Mệnh đề P̄ đúng khi và chỉ khi P ___ .' | D41: sai | E41: Gõ vào ô rồi bấm KIỂM TRA
A42: 4 | B42: Trắc nghiệm | C42: Cho P: 'Tam giác ABC là tam giác đều'. Phủ định P̄ là gì? Giải thích ngắn. | D42: P̄: 'Tam giác ABC KHÔNG phải tam giác đều'. | E42: Bấm chọn 1 trong 4 ô
A43: 5 | B43: Nhiều bước | C43: Cho P: '√2 là số hữu tỉ'. Bước 1: Xác định P đúng hay sai. Bước 2: Viết mệnh đề phủ định P̄. Bước 3: Xác định P̄ đúng hay sai. | D43: B1: P SAI (√2 vô tỉ). B2: P̄: '√2 KHÔNG phải số hữu tỉ' (hay: √2 là số vô tỉ). B3: P̄ ĐÚNG. | E43: Trả lời lần lượt từng bước
A44: 6 | B44: NỘP BÀI | C44: Một bạn viết: 'Cho P: n là số chẵn. Vậy P̄: n là số lẻ. Suy ra P và P̄ có thể CÙNG SAI khi n = 0 vì 0 không chẵn cũng không lẻ.' Tìm và sửa lỗi. | D44: Lỗi: khẳng định 0 không chẵn cũng không lẻ. Thực tế 0 LÀ số chẵn (0 = 2×0). Hơn nữa, về nguyên tắc, P và P̄ KHÔNG BAO GIỜ cùng sai — luôn có đúng một cái đúng. Sửa: với n = 0, P đúng, P̄ sai. | E44: Gõ ý chính là đủ — AI chấm ngay
...

Sheet TỔNG HỢP
A1: TỔNG HỢP 3 PHIẾU (tự tính — không gõ tay vào đây)
B3: Chặng | C3: Việc | D3: Đúng như mô tả | E3: Một phần | F3: Không đúng | G3: Chưa thử | H3: Dễ dùng TB
A4: 1 | B4: A. Vào app | C4: Mở tutor.vietanh.org, đăng nhập bằng tài khoản HỌC SINH của bạn. | D4: =COUNTIF('Người thử 1'!E5,"Đúng như mô tả")+COUNTIF('Người thử 2'!E5,"Đúng như mô tả")+COUNTIF('Người thử 3'!E5,"Đúng như mô tả") | E4: =COUNTIF('Người thử 1'!E5,"Một phần")+COUNTIF('Người thử 2'!E5,"Một phần")+COUNTIF('Người thử 3'!E5,"Một phần") | F4: =COUNTIF('Người thử 1'!E5,"Không đúng")+COUNTIF('Người thử 2'!E5,"Không đúng")+COUNTIF('Người thử 3'!E5,"Không đúng") | G4: =COUNTIF('Người thử 1'!E5,"Chưa thử")+COUNTIF('Người thử 2'!E5,"Chưa thử")+COUNTIF('Người thử 3'!E5,"Chưa thử") | H4: =IFERROR(ROUND(AVERAGE('Người thử 1'!F5,'Người thử 2'!F5,'Người thử 3'!F5),1),"")
A5: 2 | B5: A. Vào app | C5: Chọn môn Toán 10. | D5: =COUNTIF('Người thử 1'!E6,"Đúng như mô tả")+COUNTIF('Người thử 2'!E6,"Đúng như mô tả")+COUNTIF('Người thử 3'!E6,"Đúng như mô tả") | E5: =COUNTIF('Người thử 1'!E6,"Một phần")+COUNTIF('Người thử 2'!E6,"Một phần")+COUNTIF('Người thử 3'!E6,"Một phần") | F5: =COUNTIF('Người thử 1'!E6,"Không đúng")+COUNTIF('Người thử 2'!E6,"Không đúng")+COUNTIF('Người thử 3'!E6,"Không đúng") | G5: =COUNTIF('Người thử 1'!E6,"Chưa thử")+COUNTIF('Người thử 2'!E6,"Chưa thử")+COUNTIF('Người thử 3'!E6,"Chưa thử") | H5: =IFERROR(ROUND(AVERAGE('Người thử 1'!F6,'Người thử 2'!F6,'Người thử 3'!F6),1),"")
A6: 3 | B6: B. Học bài đầu | C6: Bấm vào bàn chân đang sáng. | D6: =COUNTIF('Người thử 1'!E7,"Đúng như mô tả")+COUNTIF('Người thử 2'!E7,"Đúng như mô tả")+COUNTIF('Người thử 3'!E7,"Đúng như mô tả") | E6: =COUNTIF('Người thử 1'!E7,"Một phần")+COUNTIF('Người thử 2'!E7,"Một phần")+COUNTIF('Người thử 3'!E7,"Một phần") | F6: =COUNTIF('Người thử 1'!E7,"Không đúng")+COUNTIF('Người thử 2'!E7,"Không đúng")+COUNTIF('Người thử 3'!E7,"Không đúng") | G6: =COUNTIF('Người thử 1'!E7,"Chưa thử")+COUNTIF('Người thử 2'!E7,"Chưa thử")+COUNTIF('Người thử 3'!E7,"Chưa thử") | H6: =IFERROR(ROUND(AVERAGE('Người thử 1'!F7,'Người thử 2'!F7,'Người thử 3'!F7),1),"")
A7: 4 | B7: B. Học bài đầu | C7: Làm câu 1 đến câu 4 (đáp án ở sheet ĐÁP ÁN TOÁN 10, bài 1). | D7: =COUNTIF('Người thử 1'!E8,"Đúng như mô tả")+COUNTIF('Người thử 2'!E8,"Đúng như mô tả")+COUNTIF('Người thử 3'!E8,"Đúng như mô tả") | E7: =COUNTIF('Người thử 1'!E8,"Một phần")+COUNTIF('Người thử 2'!E8,"Một phần")+COUNTIF('Người thử 3'!E8,"Một phần") | F7: =COUNTIF('Người thử 1'!E8,"Không đúng")+COUNTIF('Người thử 2'!E8,"Không đúng")+COUNTIF('Người thử 3'!E8,"Không đúng") | G7: =COUNTIF('Người thử 1'!E8,"Chưa thử")+COUNTIF('Người thử 2'!E8,"Chưa thử")+COUNTIF('Người thử 3'!E8,"Chưa thử") | H7: =IFERROR(ROUND(AVERAGE('Người thử 1'!F8,'Người thử 2'!F8,'Người thử 3'!F8),1),"")
A8: 5 | B8: B. Học bài đầu | C8: CỐ TÌNH chọn sai một câu để xem app phản ứng thế nào. | D8: =COUNTIF('Người thử 1'!E9,"Đúng như mô tả")+COUNTIF('Người thử 2'!E9,"Đúng như mô tả")+COUNTIF('Người thử 3'!E9,"Đúng như mô tả") | E8: =COUNTIF('Người thử 1'!E9,"Một phần")+COUNTIF('Người thử 2'!E9,"Một phần")+COUNTIF('Người thử 3'!E9,"Một phần") | F8: =COUNTIF('Người thử 1'!E9,"Không đúng")+COUNTIF('Người thử 2'!E9,"Không đúng")+COUNTIF('Người thử 3'!E9,"Không đúng") | G8: =COUNTIF('Người thử 1'!E9,"Chưa thử")+COUNTIF('Người thử 2'!E9,"Chưa thử")+COUNTIF('Người thử 3'!E9,"Chưa thử") | H8: =IFERROR(ROUND(AVERAGE('Người thử 1'!F9,'Người thử 2'!F9,'Người thử 3'!F9),1),"")
A9: 6 | B9: C. Câu nhiều bước | C9: Làm câu 5 — đề chia thành Bước 1, Bước 2, Bước 3. | D9: =COUNTIF('Người thử 1'!E10,"Đúng như mô tả")+COUNTIF('Người thử 2'!E10,"Đúng như mô tả")+COUNTIF('Người thử 3'!E10,"Đúng như mô tả") | E9: =COUNTIF('Người thử 1'!E10,"Một phần")+COUNTIF('Người thử 2'!E10,"Một phần")+COUNTIF('Người thử 3'!E10,"Một phần") | F9: =COUNTIF('Người thử 1'!E10,"Không đúng")+COUNTIF('Người thử 2'!E10,"Không đúng")+COUNTIF('Người thử 3'!E10,"Không đúng") | G9: =COUNTIF('Người thử 1'!E10,"Chưa thử")+COUNTIF('Người thử 2'!E10,"Chưa thử")+COUNTIF('Người thử 3'!E10,"Chưa thử") | H9: =IFERROR(ROUND(AVERAGE('Người thử 1'!F10,'Người thử 2'!F10,'Người thử 3'!F10),1),"")
A10: 7 | B10: D. Nộp bài tự luận | C10: Làm câu 6 — câu này là dạng NỘP BÀI (đáp án dài). | D10: =COUNTIF('Người thử 1'!E11,"Đúng như mô tả")+COUNTIF('Người thử 2'!E11,"Đúng như mô tả")+COUNTIF('Người thử 3'!E11,"Đúng như mô tả") | E10: =COUNTIF('Người thử 1'!E11,"Một phần")+COUNTIF('Người thử 2'!E11,"Một phần")+COUNTIF('Người thử 3'!E11,"Một phần") | F10: =COUNTIF('Người thử 1'!E11,"Không đúng")+COUNTIF('Người thử 2'!E11,"Không đúng")+COUNTIF('Người thử 3'!E11,"Không đúng") | G10: =COUNTIF('Người thử 1'!E11,"Chưa thử")+COUNTIF('Người thử 2'!E11,"Chưa thử")+COUNTIF('Người thử 3'!E11,"Chưa thử") | H10: =IFERROR(ROUND(AVERAGE('Người thử 1'!F11,'Người thử 2'!F11,'Người thử 3'!F11),1),"")
A11: 8 | B11: D. Nộp bài tự luận | C11: Xem app chấm bài gõ của bạn. | D11: =COUNTIF('Người thử 1'!E12,"Đúng như mô tả")+COUNTIF('Người thử 2'!E12,"Đúng như mô tả")+COUNTIF('Người thử 3'!E12,"Đúng như mô tả") | E11: =COUNTIF('Người thử 1'!E12,"Một phần")+COUNTIF('Người thử 2'!E12,"Một phần")+COUNTIF('Người thử 3'!E12,"Một phần") | F11: =COUNTIF('Người thử 1'!E12,"Không đúng")+COUNTIF('Người thử 2'!E12,"Không đúng")+COUNTIF('Người thử 3'!E12,"Không đúng") | G11: =COUNTIF('Người thử 1'!E12,"Chưa thử")+COUNTIF('Người thử 2'!E12,"Chưa thử")+COUNTIF('Người thử 3'!E12,"Chưa thử") | H11: =IFERROR(ROUND(AVERAGE('Người thử 1'!F12,'Người thử 2'!F12,'Người thử 3'!F12),1),"")
A12: 9 | B12: D. Nộp bài tự luận | C12: Thử nộp bằng ẢNH: chụp/chọn một ảnh bất kỳ rồi nộp (câu 7 hoặc 8). | D12: =COUNTIF('Người thử 1'!E13,"Đúng như mô tả")+COUNTIF('Người thử 2'!E13,"Đúng như mô tả")+COUNTIF('Người thử 3'!E13,"Đúng như mô tả") | E12: =COUNTIF('Người thử 1'!E13,"Một phần")+COUNTIF('Người thử 2'!E13,"Một phần")+COUNTIF('Người thử 3'!E13,"Một phần") | F12: =COUNTIF('Người thử 1'!E13,"Không đúng")+COUNTIF('Người thử 2'!E13,"Không đúng")+COUNTIF('Người thử 3'!E13,"Không đúng") | G12: =COUNTIF('Người thử 1'!E13,"Chưa thử")+COUNTIF('Người thử 2'!E13,"Chưa thử")+COUNTIF('Người thử 3'!E13,"Chưa thử") | H12: =IFERROR(ROUND(AVERAGE('Người thử 1'!F13,'Người thử 2'!F13,'Người thử 3'!F13),1),"")
A13: 10 | B13: E. Sau khi học | C13: Làm nốt các câu còn lại rồi thoát ra lộ trình. | D13: =COUNTIF('Người thử 1'!E14,"Đúng như mô tả")+COUNTIF('Người thử 2'!E14,"Đúng như mô tả")+COUNTIF('Người thử 3'!E14,"Đúng như mô tả") | E13: =COUNTIF('Người thử 1'!E14,"Một phần")+COUNTIF('Người thử 2'!E14,"Một phần")+COUNTIF('Người thử 3'!E14,"Một phần") | F13: =COUNTIF('Người thử 1'!E14,"Không đúng")+COUNTIF('Người thử 2'!E14,"Không đúng")+COUNTIF('Người thử 3'!E14,"Không đúng") | G13: =COUNTIF('Người thử 1'!E14,"Chưa thử")+COUNTIF('Người thử 2'!E14,"Chưa thử")+COUNTIF('Người thử 3'!E14,"Chưa thử") | H13: =IFERROR(ROUND(AVERAGE('Người thử 1'!F14,'Người thử 2'!F14,'Người thử 3'!F14),1),"")
A14: 11 | B14: E. Sau khi học | C14: Bấm lần lượt 4 mục dưới cùng: Ôn tập, Hạng, Mục tiêu, Tôi. | D14: =COUNTIF('Người thử 1'!E15,"Đúng như mô tả")+COUNTIF('Người thử 2'!E15,"Đúng như mô tả")+COUNTIF('Người thử 3'!E15,"Đúng như mô tả") | E14: =COUNTIF('Người thử 1'!E15,"Một phần")+COUNTIF('Người thử 2'!E15,"Một phần")+COUNTIF('Người thử 3'!E15,"Một phần") | F14: =COUNTIF('Người thử 1'!E15,"Không đúng")+COUNTIF('Người thử 2'!E15,"Không đúng")+COUNTIF('Người thử 3'!E15,"Không đúng") | G14: =COUNTIF('Người thử 1'!E15,"Chưa thử")+COUNTIF('Người thử 2'!E15,"Chưa thử")+COUNTIF('Người thử 3'!E15,"Chưa thử") | H14: =IFERROR(ROUND(AVERAGE('Người thử 1'!F15,'Người thử 2'!F15,'Người thử 3'!F15),1),"")
A15: 12 | B15: F. Phía phụ huynh | C15: Đăng xuất, đăng nhập bằng tài khoản PHỤ HUYNH của bạn (trang 'Theo dõi con'). | D15: =COUNTIF('Người thử 1'!E16,"Đúng như mô tả")+COUNTIF('Người thử 2'!E16,"Đúng như mô tả")+COUNTIF('Người thử 3'!E16,"Đúng như mô tả") | E15: =COUNTIF('Người thử 1'!E16,"Một phần")+COUNTIF('Người thử 2'!E16,"Một phần")+COUNTIF('Người thử 3'!E16,"Một phần") | F15: =COUNTIF('Người thử 1'!E16,"Không đúng")+COUNTIF('Người thử 2'!E16,"Không đúng")+COUNTIF('Người thử 3'!E16,"Không đúng") | G15: =COUNTIF('Người thử 1'!E16,"Chưa thử")+COUNTIF('Người thử 2'!E16,"Chưa thử")+COUNTIF('Người thử 3'!E16,"Chưa thử") | H15: =IFERROR(ROUND(AVERAGE('Người thử 1'!F16,'Người thử 2'!F16,'Người thử 3'!F16),1),"")
... A19: 16 | B19: I. Trên điện thoại | C19: Mở lại tutor.vietanh.org bằng điện thoại, làm thử 2–3 câu. | D19: =COUNTIF('Người thử 1'!E20,"Đúng như mô tả")+COUNTIF('Người thử 2'!E20,"Đúng như mô tả")+COUNTIF('Người thử 3'!E20,"Đúng như mô tả") | E19: =COUNTIF('Người thử 1'!E20,"Một phần")+COUNTIF('Người thử 2'!E20,"Một phần")+COUNTIF('Người thử 3'!E20,"Một phần") | F19: =COUNTIF('Người thử 1'!E20,"Không đúng")+COUNTIF('Người thử 2'!E20,"Không đúng")+COUNTIF('Người thử 3'!E20,"Không đúng") | G19: =COUNTIF('Người thử 1'!E20,"Chưa thử")+COUNTIF('Người thử 2'!E20,"Chưa thử")+COUNTIF('Người thử 3'!E20,"Chưa thử") | H19: =IFERROR(ROUND(AVERAGE('Người thử 1'!F20,'Người thử 2'!F20,'Người thử 3'!F20),1),"")
B21: Chặng nào có ô 'Không đúng' ≥ 1 là chỗ phải sửa trước. Cột 'Dễ dùng TB' dưới 3,5 là chỗ khó dùng dù chạy đúng.
