Workbook

Sheet Tổng quan
A1: TIMELINE DỰ ÁN — AI Personal Tutor Trường Việt Anh
A2: Bám sát PRD v3 · 100% = Pilot production Việt Anh trọn vẹn (Toán 10 + Anh 10)
A4: % HOÀN THÀNH HIỆN TẠI
A5: =Checklist!G117/100
A6: (Xong = 100% trọng số · Đang = 50% · Chưa = 0%. Đổi trạng thái ở Checklist → ô này tự nhảy.)
A8: TIẾN ĐỘ THEO KHU VỰC
A9: Khu vực | B9: Trọng số % | C9: % đạt | D9: Ghi chú
A10: A. Hạ tầng & Schema DB | B10: =SUMIF(Checklist!$A$2:$A$116,$A10,Checklist!$E$2:$E$116) | C10: =SUMIF(Checklist!$A$2:$A$116,$A10,Checklist!$G$2:$G$116) | D10: =IF(B10=0,"",TEXT(C10/B10,"0%")&" của khu vực")
A11: B. Auth & RBAC | B11: =SUMIF(Checklist!$A$2:$A$116,$A11,Checklist!$E$2:$E$116) | C11: =SUMIF(Checklist!$A$2:$A$116,$A11,Checklist!$G$2:$G$116) | D11: =IF(B11=0,"",TEXT(C11/B11,"0%")&" của khu vực")
A12: C. Engine sư phạm | B12: =SUMIF(Checklist!$A$2:$A$116,$A12,Checklist!$E$2:$E$116) | C12: =SUMIF(Checklist!$A$2:$A$116,$A12,Checklist!$G$2:$G$116) | D12: =IF(B12=0,"",TEXT(C12/B12,"0%")&" của khu vực")
A13: D. Nội dung Toán 10 | B13: =SUMIF(Checklist!$A$2:$A$116,$A13,Checklist!$E$2:$E$116) | C13: =SUMIF(Checklist!$A$2:$A$116,$A13,Checklist!$G$2:$G$116) | D13: =IF(B13=0,"",TEXT(C13/B13,"0%")&" của khu vực")
A14: E. Nội dung Tiếng Anh 10 | B14: =SUMIF(Checklist!$A$2:$A$116,$A14,Checklist!$E$2:$E$116) | C14: =SUMIF(Checklist!$A$2:$A$116,$A14,Checklist!$G$2:$G$116) | D14: =IF(B14=0,"",TEXT(C14/B14,"0%")&" của khu vực")
A15: F. Dạng câu & chấm | B15: =SUMIF(Checklist!$A$2:$A$116,$A15,Checklist!$E$2:$E$116) | C15: =SUMIF(Checklist!$A$2:$A$116,$A15,Checklist!$G$2:$G$116) | D15: =IF(B15=0,"",TEXT(C15/B15,"0%")&" của khu vực")
A16: G. UX học sinh | B16: =SUMIF(Checklist!$A$2:$A$116,$A16,Checklist!$E$2:$E$116) | C16: =SUMIF(Checklist!$A$2:$A$116,$A16,Checklist!$G$2:$G$116) | D16: =IF(B16=0,"",TEXT(C16/B16,"0%")&" của khu vực")
A17: H. Công cụ Giáo viên | B17: =SUMIF(Checklist!$A$2:$A$116,$A17,Checklist!$E$2:$E$116) | C17: =SUMIF(Checklist!$A$2:$A$116,$A17,Checklist!$G$2:$G$116) | D17: =IF(B17=0,"",TEXT(C17/B17,"0%")&" của khu vực")
A18: I. Phụ huynh | B18: =SUMIF(Checklist!$A$2:$A$116,$A18,Checklist!$E$2:$E$116) | C18: =SUMIF(Checklist!$A$2:$A$116,$A18,Checklist!$G$2:$G$116) | D18: =IF(B18=0,"",TEXT(C18/B18,"0%")&" của khu vực")
A19: J. Admin & vận hành | B19: =SUMIF(Checklist!$A$2:$A$116,$A19,Checklist!$E$2:$E$116) | C19: =SUMIF(Checklist!$A$2:$A$116,$A19,Checklist!$G$2:$G$116) | D19: =IF(B19=0,"",TEXT(C19/B19,"0%")&" của khu vực")
A20: K. PDPL tuân thủ | B20: =SUMIF(Checklist!$A$2:$A$116,$A20,Checklist!$E$2:$E$116) | C20: =SUMIF(Checklist!$A$2:$A$116,$A20,Checklist!$G$2:$G$116) | D20: =IF(B20=0,"",TEXT(C20/B20,"0%")&" của khu vực")
A21: L. Nhà máy nội dung | B21: =SUMIF(Checklist!$A$2:$A$116,$A21,Checklist!$E$2:$E$116) | C21: =SUMIF(Checklist!$A$2:$A$116,$A21,Checklist!$G$2:$G$116) | D21: =IF(B21=0,"",TEXT(C21/B21,"0%")&" của khu vực")
... A25: P. Nhân bản môn mới | B25: =SUMIF(Checklist!$A$2:$A$116,$A25,Checklist!$E$2:$E$116) | C25: =SUMIF(Checklist!$A$2:$A$116,$A25,Checklist!$G$2:$G$116) | D25: =IF(B25=0,"",TEXT(C25/B25,"0%")&" của khu vực")
A27: MỐC LỘ TRÌNH (PRD v3 §12)
A28: Mốc | B28: Trạng thái | C28: Tiêu chí
A29: M0 Sẵn sàng | B29: Xong | C29: Supabase + schema v2 + RLS + Studio pipeline
A30: M1 Khung KG | B30: Xong | C30: Trạm 1–2 xong 1 chương/môn
A31: M2 Nguyên mẫu 1 chương trọn 6 trạm | B31: Xong | C31: Nạp được vào Supabase
A32: M3 Vận hành thử | B32: Xong | C32: Chat+Tutor; truy ngược + thang Socratic verify LIVE
A33: M4 Phủ 50%/môn + A/B | B33: Đang | C33: Toán 10 ~đủ; Anh đang; A/B chưa
A34: M5 Phủ trọn Toán 10 + Anh 10 + số liệu | B34: Chưa | C34: Đích 100% pilot
A35: M6 Nhân bản (GDKTPL…) | B35: Chưa | C35: cửa importer đã sẵn — v-next
A37: ĐẠT 100% NGHĨA LÀ (PRD v3 §14)
A38: 1. Nội dung: Toán 10 + Tiếng Anh 10 phủ trọn, 'Đã phát hành', có thống kê câu.
A39: 2. Engine + 17 dạng câu chạy đúng end-to-end trên production.
A40: 3. Đủ vai & công cụ: HS học · GV theo dõi/duyệt/điều chỉnh · PH xem tiến độ · Admin cảnh báo.
A41: 4. Tuân thủ PDPL đầy đủ (đồng thuận kép + rút đồng ý + ẩn danh) + gamification nỗ lực.
A42: 5. Đo hiệu quả A/B + nhà máy nội dung vận hành để nhân bản môn kế.
A43: Ngoài 100% (v-next): IRT/CAT + Knowledge Tracing · SSO/Classroom/OCR · báo cáo Zalo · nhân bản đa môn.
A45: CHÚ THÍCH: Xong = 100% trọng số · Đang = 50% · Chưa = 0% · mỗi đầu việc ≤ 3% · tổng = 100%

Sheet Checklist
A1: Khu vực | B1: Mã | C1: Đầu việc | D1: Điểm | E1: Trọng số % | F1: Trạng thái | G1: % đạt | H1: Ghi chú
A2: A. Hạ tầng & Schema DB | B2: A1 | C2: Tạo Supabase project production + Postgres | D2: 1 | E2: =D2/SUM($D$2:$D$116)*100 | F2: Xong | G2: =E2*IF(F2="Xong",1,IF(F2="Đang",0.5,0))
A3: A. Hạ tầng & Schema DB | B3: A2 | C3: Bảng KG core (kg_versions/nodes/edges/node_tiers) theo schema v2 | D3: 2 | E3: =D3/SUM($D$2:$D$116)*100 | F3: Xong | G3: =E3*IF(F3="Xong",1,IF(F3="Đang",0.5,0))
A4: A. Hạ tầng & Schema DB | B4: A3 | C4: Bảng resources + cột embedding pgvector | D4: 1 | E4: =D4/SUM($D$2:$D$116)*100 | F4: Xong | G4: =E4*IF(F4="Xong",1,IF(F4="Đang",0.5,0))
A5: A. Hạ tầng & Schema DB | B5: A4 | C5: Bảng questions (DOK+độ khó tách, distractor, tham số, stats) | D5: 2 | E5: =D5/SUM($D$2:$D$116)*100 | F5: Xong | G5: =E5*IF(F5="Xong",1,IF(F5="Đang",0.5,0))
A6: A. Hạ tầng & Schema DB | B6: A5 | C6: Bảng socratic_ladders (rungs/bottom_out/cổng nỗ lực) | D6: 1 | E6: =D6/SUM($D$2:$D$116)*100 | F6: Xong | G6: =E6*IF(F6="Xong",1,IF(F6="Đang",0.5,0))
A7: A. Hạ tầng & Schema DB | B7: A6 | C7: Bảng vận hành (sessions/attempts/mastery_evidence/node_state) | D7: 2 | E7: =D7/SUM($D$2:$D$116)*100 | F7: Xong | G7: =E7*IF(F7="Xong",1,IF(F7="Đang",0.5,0))
A8: A. Hạ tầng & Schema DB | B8: A7 | C8: Bảng consent/audit_logs/token_usage/flags/review_queue/overrides | D8: 2 | E8: =D8/SUM($D$2:$D$116)*100 | F8: Xong | G8: =E8*IF(F8="Xong",1,IF(F8="Đang",0.5,0))
A9: A. Hạ tầng & Schema DB | B9: A8 | C9: Bảng student_xp + classes + user_roles | D9: 1 | E9: =D9/SUM($D$2:$D$116)*100 | F9: Xong | G9: =E9*IF(F9="Xong",1,IF(F9="Đang",0.5,0))
A10: A. Hạ tầng & Schema DB | B10: A9 | C10: Migrations 0001–0011 hợp nhất, versioned | D10: 1 | E10: =D10/SUM($D$2:$D$116)*100 | F10: Xong | G10: =E10*IF(F10="Xong",1,IF(F10="Đang",0.5,0))
A11: A. Hạ tầng & Schema DB | B11: A10 | C11: Auth provisioning trigger (handle_new_user, domain-gate) | D11: 1 | E11: =D11/SUM($D$2:$D$116)*100 | F11: Xong | G11: =E11*IF(F11="Xong",1,IF(F11="Đang",0.5,0))
A12: B. Auth & RBAC | B12: B1 | C12: Google SSO (skipBrowserRedirect + navigate) | D12: 1 | E12: =D12/SUM($D$2:$D$116)*100 | F12: Xong | G12: =E12*IF(F12="Xong",1,IF(F12="Đang",0.5,0))
A13: B. Auth & RBAC | B13: B2 | C13: Parent magic-link (signInWithOtp) | D13: 1 | E13: =D13/SUM($D$2:$D$116)*100 | F13: Xong | G13: =E13*IF(F13="Xong",1,IF(F13="Đang",0.5,0))
... A31: C. Engine sư phạm | B31: C13 | C31: Guide agent (Socratic prompt, không lộ đáp án) | D31: 1 | E31: =D31/SUM($D$2:$D$116)*100 | F31: Xong | G31: =E31*IF(F31="Xong",1,IF(F31="Đang",0.5,0))
A32: C. Engine sư phạm | B32: C14 | C32: Đào thải câu kém theo p-value/discrimination | D32: 2 | E32: =D32/SUM($D$2:$D$116)*100 | F32: Đang | G32: =E32*IF(F32="Xong",1,IF(F32="Đang",0.5,0)) | H32: có cột stats, chưa cron retire tự động
A33: D. Nội dung Toán 10 | B33: D1 | C33: KG nodes Toán 10 (204 node / 9 chương) | D33: 2 | E33: =D33/SUM($D$2:$D$116)*100 | F33: Xong | G33: =E33*IF(F33="Xong",1,IF(F33="Đang",0.5,0))
A34: D. Nội dung Toán 10 | B34: D2 | C34: Cạnh prerequisite_hard (259) | D34: 1 | E34: =D34/SUM($D$2:$D$116)*100 | F34: Xong | G34: =E34*IF(F34="Xong",1,IF(F34="Đang",0.5,0))
A35: D. Nội dung Toán 10 | B35: D3 | C35: Ngân hàng câu Toán 10 (1416 câu active) | D35: 2 | E35: =D35/SUM($D$2:$D$116)*100 | F35: Xong | G35: =E35*IF(F35="Xong",1,IF(F35="Đang",0.5,0))
A36: D. Nội dung Toán 10 | B36: D4 | C36: Nạp thang Socratic C1–C8 (2607 thang) | D36: 2 | E36: =D36/SUM($D$2:$D$116)*100 | F36: Xong | G36: =E36*IF(F36="Xong",1,IF(F36="Đang",0.5,0))
A37: D. Nội dung Toán 10 | B37: D5 | C37: Thang Socratic Chương 9 (22 thang/12 node) | D37: 1 | E37: =D37/SUM($D$2:$D$116)*100 | F37: Xong | G37: =E37*IF(F37="Xong",1,IF(F37="Đang",0.5,0)) | H37: Studio đã soạn C09; nạp qua import-ladders-c09.mjs
A38: D. Nội dung Toán 10 | B38: D6 | C38: Hiệu chuẩn/nghiệm thu thống kê câu Toán 10 | D38: 2 | E38: =D38/SUM($D$2:$D$116)*100 | F38: Đang | G38: =E38*IF(F38="Xong",1,IF(F38="Đang",0.5,0))
A39: E. Nội dung Tiếng Anh 10 | B39: E1 | C39: KG version Anh 10 (Global Success) | D39: 1 | E39: =D39/SUM($D$2:$D$116)*100 | F39: Xong | G39: =E39*IF(F39="Xong",1,IF(F39="Đang",0.5,0))
A40: E. Nội dung Tiếng Anh 10 | B40: E2 | C40: Ngân hàng 1551 câu sync từ Studio | D40: 2 | E40: =D40/SUM($D$2:$D$116)*100 | F40: Xong | G40: =E40*IF(F40="Xong",1,IF(F40="Đang",0.5,0))
A41: E. Nội dung Tiếng Anh 10 | B41: E3 | C41: Phủ 17 dạng câu (mcq/điền/dung_sai/sap_xep/noi_cot/viết/nói…) | D41: 2 | E41: =D41/SUM($D$2:$D$116)*100 | F41: Xong | G41: =E41*IF(F41="Xong",1,IF(F41="Đang",0.5,0))
A42: E. Nội dung Tiếng Anh 10 | B42: E4 | C42: Rubric riêng từng câu (Studio cấp theo khuôn kỹ năng) | D42: 2 | E42: =D42/SUM($D$2:$D$116)*100 | F42: Chưa | G42: =E42*IF(F42="Xong",1,IF(F42="Đang",0.5,0)) | H42: đã chốt khuôn, chờ Studio
A43: E. Nội dung Tiếng Anh 10 | B43: E5 | C43: Nội dung Nghe (nghe) + transcript/audio | D43: 2 | E43: =D43/SUM($D$2:$D$116)*100 | F43: Chưa | G43: =E43*IF(F43="Xong",1,IF(F43="Đang",0.5,0)) | H43: DB đang 0 câu nghe
A44: E. Nội dung Tiếng Anh 10 | B44: E6 | C44: Thang Socratic cho Anh 10 | D44: 2 | E44: =D44/SUM($D$2:$D$116)*100 | F44: Chưa | G44: =E44*IF(F44="Xong",1,IF(F44="Đang",0.5,0))
A45: E. Nội dung Tiếng Anh 10 | B45: E7 | C45: Nghiệm thu/thống kê câu Anh 10 | D45: 2 | E45: =D45/SUM($D$2:$D$116)*100 | F45: Chưa | G45: =E45*IF(F45="Xong",1,IF(F45="Đang",0.5,0))
A46: F. Dạng câu & chấm | B46: F1 | C46: MCQ + điền đáp án (chấm CAS) | D46: 1 | E46: =D46/SUM($D$2:$D$116)*100 | F46: Xong | G46: =E46*IF(F46="Xong",1,IF(F46="Đang",0.5,0))
A47: F. Dạng câu & chấm | B47: F2 | C47: dung_sai (nút Đúng/Sai) | D47: 1 | E47: =D47/SUM($D$2:$D$116)*100 | F47: Xong | G47: =E47*IF(F47="Xong",1,IF(F47="Đang",0.5,0)) | H47: Đợt A
A48: F. Dạng câu & chấm | B48: F3 | C48: sap_xep (kéo-thả xếp thứ tự) | D48: 2 | E48: =D48/SUM($D$2:$D$116)*100 | F48: Xong | G48: =E48*IF(F48="Xong",1,IF(F48="Đang",0.5,0)) | H48: Đợt A
A49: F. Dạng câu & chấm | B49: F4 | C49: noi_cot (kéo-thả nối cột) | D49: 2 | E49: =D49/SUM($D$2:$D$116)*100 | F49: Xong | G49: =E49*IF(F49="Xong",1,IF(F49="Đang",0.5,0)) | H49: Đợt A
A50: F. Dạng câu & chấm | B50: F5 | C50: Bộ chấm cấu trúc tất định (dãy/tập cặp/true-false) | D50: 2 | E50: =D50/SUM($D$2:$D$116)*100 | F50: Xong | G50: =E50*IF(F50="Xong",1,IF(F50="Đang",0.5,0))
A51: F. Dạng câu & chấm | B51: F6 | C51: Parse đề dẫn đường bằng dap_an (server, 100%/91%) | D51: 2 | E51: =D51/SUM($D$2:$D$116)*100 | F51: Xong | G51: =E51*IF(F51="Xong",1,IF(F51="Đang",0.5,0))
A52: F. Dạng câu & chấm | B52: F7 | C52: Viết (textarea) + chấm rubric | D52: 1 | E52: =D52/SUM($D$2:$D$116)*100 | F52: Xong | G52: =E52*IF(F52="Xong",1,IF(F52="Đang",0.5,0))
A53: F. Dạng câu & chấm | B53: F8 | C53: Nói (SpeakBox STT) + chấm rubric | D53: 1 | E53: =D53/SUM($D$2:$D$116)*100 | F53: Xong | G53: =E53*IF(F53="Xong",1,IF(F53="Đang",0.5,0))
A54: F. Dạng câu & chấm | B54: F9 | C54: Rubric theo kỹ năng (Viết/Nói/Lập luận) có điểm | D54: 2 | E54: =D54/SUM($D$2:$D$116)*100 | F54: Xong | G54: =E54*IF(F54="Xong",1,IF(F54="Đang",0.5,0)) | H54: Đợt B
A55: F. Dạng câu & chấm | B55: F10 | C55: Scorecard UI (điểm từng tiêu chí) | D55: 1 | E55: =D55/SUM($D$2:$D$116)*100 | F55: Xong | G55: =E55*IF(F55="Xong",1,IF(F55="Đang",0.5,0)) | H55: Đợt B
A56: F. Dạng câu & chấm | B56: F11 | C56: Nút Nghe (Web Speech TTS) | D56: 1 | E56: =D56/SUM($D$2:$D$116)*100 | F56: Xong | G56: =E56*IF(F56="Xong",1,IF(F56="Đang",0.5,0)) | H56: Đợt C
A57: F. Dạng câu & chấm | B57: F12 | C57: KaTeX render công thức | D57: 1 | E57: =D57/SUM($D$2:$D$116)*100 | F57: Xong | G57: =E57*IF(F57="Xong",1,IF(F57="Đang",0.5,0))
...
